<?xml version="1.0"?>
<robot name="exemplo">

  <link name="base_link">
    <visual>
      <origin rpy="0 0 0" xyz="0 0 0"/>
      <geometry>
        <mesh filename="package://tutorial_urdf/meshes/base_link.stl" scale="0.001 0.001 0.001"/>
      </geometry>

    </visual>
  </link>

  <joint name="join_1" type="revolute">
    <origin xyz="0 0 0.14695" rpy="0 0 0"/>
    <parent link="base_link"/>
    <child link="link_1"/>
    <axis xyz="0 0 1"/>
    <limit upper="1.570796" lower="-1.570796" effort="100" velocity="2"/>
  </joint>

  <link name="link_1">
    <visual>
      <origin rpy="0 0 0" xyz="0 0 0"/>
      <geometry>
        <mesh filename="package://tutorial_urdf/meshes/link_1.stl" scale="0.001 0.001 0.001"/>
      </geometry>
    </visual>
  </link>

</robot>